Workbook

Sheet Consolidation
A1: Brand | B1: Crash free users | C1: App Hangs | D1: App size | E1: ASTI | F1: STTI | G1: Frozen Frames | H1: Skipped Frames | M1: Riders count | N1: Weight Rider ID
A2: Foodpanda | B2: =TRUNC(MAX(0,MIN(100,(1-SUMIFS(Dashboard!$X:$X,Dashboard!$Z:$Z,"*"&$A2&"*")/IF(SUMIFS(Dashboard!$V:$V,Dashboard!$U:$U,"*"&$A2&"*")>0,SUMIFS(Dashboard!$V:$V,Dashboard!$U:$U,"*"&$A2&"*"),M2*31))*100)),2) | C2: =TRUNC(MAX(0,MIN(100,(1-SUMIFS(Dashboard!$AB:$AB,Dashboard!$AD:$AD,"*"&$A2&"*")/IF(SUMIFS(Dashboard!$V:$V,Dashboard!$U:$U,"*"&$A2&"*")>0,SUMIFS(Dashboard!$V:$V,Dashboard!$U:$U,"*"&$A2&"*"),M2*31))*100)),2) | D2: 77.8 | E2: 4.34 | F2: 1.1 | G2: 2.64 | H2: 0.92 | M2: 78203 | N2: 0.3966
A3: Foodora | B3: =TRUNC(MAX(0,MIN(100,(1-SUMIFS(Dashboard!$X:$X,Dashboard!$Z:$Z,"*"&$A3&"*")/IF(SUMIFS(Dashboard!$V:$V,Dashboard!$U:$U,"*"&$A3&"*")>0,SUMIFS(Dashboard!$V:$V,Dashboard!$U:$U,"*"&$A3&"*"),M3*31))*100)),2) | C3: =TRUNC(MAX(0,MIN(100,(1-SUMIFS(Dashboard!$AB:$AB,Dashboard!$AD:$AD,"*"&$A3&"*")/IF(SUMIFS(Dashboard!$V:$V,Dashboard!$U:$U,"*"&$A3&"*")>0,SUMIFS(Dashboard!$V:$V,Dashboard!$U:$U,"*"&$A3&"*"),M3*31))*100)),2) | D3: 83.2 | E3: 4.34 | F3: 1.1 | G3: 2.64 | H3: 0.92 | M3: 14946 | N3: 0.0758
A4: Talabat | B4: =TRUNC(MAX(0,MIN(100,(1-SUMIFS(Dashboard!$X:$X,Dashboard!$Z:$Z,"*"&$A4&"*")/IF(SUMIFS(Dashboard!$V:$V,Dashboard!$U:$U,"*"&$A4&"*")>0,SUMIFS(Dashboard!$V:$V,Dashboard!$U:$U,"*"&$A4&"*"),M4*31))*100)),2) | C4: =TRUNC(MAX(0,MIN(100,(1-SUMIFS(Dashboard!$AB:$AB,Dashboard!$AD:$AD,"*"&$A4&"*")/IF(SUMIFS(Dashboard!$V:$V,Dashboard!$U:$U,"*"&$A4&"*")>0,SUMIFS(Dashboard!$V:$V,Dashboard!$U:$U,"*"&$A4&"*"),M4*31))*100)),2) | D4: 77.8 | E4: 4.34 | F4: 1.1 | G4: 2.64 | H4: 0.92 | M4: 16988 | N4: 0.0861
A5: pedidosya | B5: =TRUNC(MAX(0,MIN(100,(1-SUMIFS(Dashboard!$X:$X,Dashboard!$Z:$Z,"*"&$A5&"*")/IF(SUMIFS(Dashboard!$V:$V,Dashboard!$U:$U,"*"&$A5&"*")>0,SUMIFS(Dashboard!$V:$V,Dashboard!$U:$U,"*"&$A5&"*"),M5*31))*100)),2) | C5: =TRUNC(MAX(0,MIN(100,(1-SUMIFS(Dashboard!$AB:$AB,Dashboard!$AD:$AD,"*"&$A5&"*")/IF(SUMIFS(Dashboard!$V:$V,Dashboard!$U:$U,"*"&$A5&"*")>0,SUMIFS(Dashboard!$V:$V,Dashboard!$U:$U,"*"&$A5&"*"),M5*31))*100)),2) | D5: 68.4 | E5: 4.34 | F5: 1.1 | G5: 2.64 | H5: 0.92 | M5: 20641 | N5: 0.1047
A6: HungerStation | B6: =TRUNC(MAX(0,MIN(100,(1-SUMIFS(Dashboard!$X:$X,Dashboard!$Z:$Z,"*"&$A6&"*")/IF(SUMIFS(Dashboard!$V:$V,Dashboard!$U:$U,"*"&$A6&"*")>0,SUMIFS(Dashboard!$V:$V,Dashboard!$U:$U,"*"&$A6&"*"),M6*31))*100)),2) | C6: =TRUNC(MAX(0,MIN(100,(1-SUMIFS(Dashboard!$AB:$AB,Dashboard!$AD:$AD,"*"&$A6&"*")/IF(SUMIFS(Dashboard!$V:$V,Dashboard!$U:$U,"*"&$A6&"*")>0,SUMIFS(Dashboard!$V:$V,Dashboard!$U:$U,"*"&$A6&"*"),M6*31))*100)),2) | D6: 78.3 | E6: 4.34 | F6: 1.1 | G6: 2.64 | H6: 0.92 | M6: 10630 | N6: 0.0539
A7: Yemeksepeti | B7: =TRUNC(MAX(0,MIN(100,(1-SUMIFS(Dashboard!$X:$X,Dashboard!$Z:$Z,"*"&$A7&"*")/IF(SUMIFS(Dashboard!$V:$V,Dashboard!$U:$U,"*"&$A7&"*")>0,SUMIFS(Dashboard!$V:$V,Dashboard!$U:$U,"*"&$A7&"*"),M7*31))*100)),2) | C7: =TRUNC(MAX(0,MIN(100,(1-SUMIFS(Dashboard!$AB:$AB,Dashboard!$AD:$AD,"*"&$A7&"*")/IF(SUMIFS(Dashboard!$V:$V,Dashboard!$U:$U,"*"&$A7&"*")>0,SUMIFS(Dashboard!$V:$V,Dashboard!$U:$U,"*"&$A7&"*"),M7*31))*100)),2) | D7: 78.3 | E7: 4.34 | F7: 1.1 | G7: 2.64 | H7: 0.92 | M7: 2186 | N7: 0.0111
A8: Glovo | B8: =TRUNC(MAX(0,MIN(100,(1-SUMIFS(Dashboard!$X:$X,Dashboard!$Z:$Z,"*"&$A8&"*")/IF(SUMIFS(Dashboard!$V:$V,Dashboard!$U:$U,"*"&$A8&"*")>0,SUMIFS(Dashboard!$V:$V,Dashboard!$U:$U,"*"&$A8&"*"),M8*31))*100)),2) | C8: =TRUNC(MAX(0,MIN(100,(1-SUMIFS(Dashboard!$AB:$AB,Dashboard!$AD:$AD,"*"&$A8&"*")/IF(SUMIFS(Dashboard!$V:$V,Dashboard!$U:$U,"*"&$A8&"*")>0,SUMIFS(Dashboard!$V:$V,Dashboard!$U:$U,"*"&$A8&"*"),M8*31))*100)),2) | D8: 77.9 | E8: 4.34 | F8: 1.1 | G8: 2.64 | H8: 0.92 | M8: 46896 | N8: 0.2378
A9: Woowa | B9: =TRUNC(MAX(0,MIN(100,(1-SUMIFS(Dashboard!$X:$X,Dashboard!$Z:$Z,"*"&$A9&"*")/IF(SUMIFS(Dashboard!$V:$V,Dashboard!$U:$U,"*"&$A9&"*")>0,SUMIFS(Dashboard!$V:$V,Dashboard!$U:$U,"*"&$A9&"*"),M9*31))*100)),2) | C9: =TRUNC(MAX(0,MIN(100,(1-SUMIFS(Dashboard!$AB:$AB,Dashboard!$AD:$AD,"*"&$A9&"*")/IF(SUMIFS(Dashboard!$V:$V,Dashboard!$U:$U,"*"&$A9&"*")>0,SUMIFS(Dashboard!$V:$V,Dashboard!$U:$U,"*"&$A9&"*"),M9*31))*100)),2) | D9: 78 | E9: 4.34 | F9: 1.1 | G9: 2.64 | H9: 0.92 | M9: 731 | N9: 0.0037
A10: efood | B10: =TRUNC(MAX(0,MIN(100,(1-SUMIFS(Dashboard!$X:$X,Dashboard!$Z:$Z,"*"&$A10&"*")/IF(SUMIFS(Dashboard!$V:$V,Dashboard!$U:$U,"*"&$A10&"*")>0,SUMIFS(Dashboard!$V:$V,Dashboard!$U:$U,"*"&$A10&"*"),M10*31))*100)),2) | C10: =TRUNC(MAX(0,MIN(100,(1-SUMIFS(Dashboard!$AB:$AB,Dashboard!$AD:$AD,"*"&$A10&"*")/IF(SUMIFS(Dashboard!$V:$V,Dashboard!$U:$U,"*"&$A10&"*")>0,SUMIFS(Dashboard!$V:$V,Dashboard!$U:$U,"*"&$A10&"*"),M10*31))*100)),2) | D10: 68.1 | E10: 4.34 | F10: 1.1 | G10: 2.64 | H10: 0.92 | M10: 5258 | N10: 0.0267
A11: Foody | B11: =TRUNC(MAX(0,MIN(100,(1-SUMIFS(Dashboard!$X:$X,Dashboard!$Z:$Z,"*"&$A11&"*")/IF(SUMIFS(Dashboard!$V:$V,Dashboard!$U:$U,"*"&$A11&"*")>0,SUMIFS(Dashboard!$V:$V,Dashboard!$U:$U,"*"&$A11&"*"),M11*31))*100)),2) | C11: =TRUNC(MAX(0,MIN(100,(1-SUMIFS(Dashboard!$AB:$AB,Dashboard!$AD:$AD,"*"&$A11&"*")/IF(SUMIFS(Dashboard!$V:$V,Dashboard!$U:$U,"*"&$A11&"*")>0,SUMIFS(Dashboard!$V:$V,Dashboard!$U:$U,"*"&$A11&"*"),M11*31))*100)),2) | D11: 68.1 | E11: 4.34 | F11: 1.1 | G11: 2.64 | H11: 0.92 | M11: 729 | N11: 0.0037
A12: AVG | B12: =TRUNC(SUMPRODUCT(B2:B11,N2:N11),2) | C12: =TRUNC(SUMPRODUCT(C2:C11,N2:N11),2) | D12: =TRUNC(SUMPRODUCT(D2:D11,N2:N11),2) | E12: =TRUNC(SUMPRODUCT(E2:E11,N2:N11),2) | F12: =TRUNC(SUMPRODUCT(F2:F11,N2:N11),2) | G12: =TRUNC(SUMPRODUCT(G2:G11,N2:N11),2) | H12: =TRUNC(SUMPRODUCT(H2:H11,N2:N11),2)
A13: AQS | B13: =MIN(100,MAX(0,(((B12-99.7)/(99.9-99.7))*50)+50))*35% | C13: =MIN(100,MAX(0,(((C12-99.7)/(99.9-99.7))*50)+50))*25% | D13: =MIN(100,MAX(0,(((D12-75)/(60-75))*50)+50))*2% | E13: =MIN(100,MAX(0,(((E12-4)/(2-4))*50)+50))*10% | F13: =MIN(100,MAX(0,(((F12-1.5)/(0.5-1.5))*50)+50))*10% | G13: =MIN(100,MAX(0,(((G12-3)/(1-3))*50)+50))*13% | H13: =MIN(100,MAX(0,(((H12-2)/(1-2))*50)+50))*5% | M13: =SUM(M2:M11) | N13: =SUM(N2:N11)
A15: FINAL AQS = | B15: =ROUND(SUM(B13:H13),2)
A17: ⚠ App size, ASTI and STTI have the older values, not recently updated. Update these columns manually before sharing. For the accurate AQS score, update these values.

Sheet Dashboard
A1: CFU part in AQS | B1: 60 | C1: Date | D1: Total users count (ios_User_Count) | E1: Crashed users count (Query) | G1: CFU % | K1: Hang user count (Query) | L1: Hang free % | N1: Projected AQS including hangs | T1: dt | U1: appId | V1: user_count | X1: CRASH_USERS | Y1: day | Z1: Brand | AB1: HANG_USERS | AC1: day | AD1: Brand
A2: base AQS score | B2: 32.65 | C2: 2026-10-01 | D2: =SUMIFS(V:V,U:U,"*"&$B$10&"*",T:T,C2) | E2: =SUMIFS(X:X,Z:Z,"*"&$B$10&"*",Y:Y,C2) | G2: =ROUND(MAX(0,MIN(100,(1-E2/IF(D2>0,D2,SUMIFS(Consolidation!$M:$M,Consolidation!$A:$A,"*"&$B$10&"*")/31))*100)),2) | H2: =MIN(1,(G2-$B$3)/($B$4-$B$3))*$B$1 | K2: =SUMIFS(AB:AB,AD:AD,"*"&$B$10&"*",AC:AC,C2) | L2: =ROUND(MAX(0,MIN(100,100*(1-K2/IF(D2>0,D2,SUMIFS(Consolidation!$M:$M,Consolidation!$A:$A,"*"&$B$10&"*")/31)))),2) | M2: =MAX(0,(L2-$B$6)/($B$7-$B$6)*$B$8) | N2: =$B$2+H2+M2 | X2: 76 | Y2: 2026-10-01 | Z2: com.logistics.rider.foodpanda | AB2: 310 | AC2: 2026-10-01 | AD2: com.logistics.rider.foodpanda
A3: CFU minimum | B3: 99.5 | C3: 2026-10-02 | D3: =SUMIFS(V:V,U:U,"*"&$B$10&"*",T:T,C3) | E3: =SUMIFS(X:X,Z:Z,"*"&$B$10&"*",Y:Y,C3) | G3: =ROUND(MAX(0,MIN(100,(1-E3/IF(D3>0,D3,SUMIFS(Consolidation!$M:$M,Consolidation!$A:$A,"*"&$B$10&"*")/31))*100)),2) | H3: =MIN(1,(G3-$B$3)/($B$4-$B$3))*$B$1 | K3: =SUMIFS(AB:AB,AD:AD,"*"&$B$10&"*",AC:AC,C3) | L3: =ROUND(MAX(0,MIN(100,100*(1-K3/IF(D3>0,D3,SUMIFS(Consolidation!$M:$M,Consolidation!$A:$A,"*"&$B$10&"*")/31)))),2) | M3: =MAX(0,(L3-$B$6)/($B$7-$B$6)*$B$8) | N3: =$B$2+H3+M3 | X3: 9 | Y3: 2026-10-01 | Z3: com.logistics.rider.foodpanda | AB3: 34 | AC3: 2026-10-01 | AD3: com.logistics.rider.foodpanda
A4: CFU maximum | B4: 99.9 | C4: 2026-10-03 | D4: =SUMIFS(V:V,U:U,"*"&$B$10&"*",T:T,C4) | E4: =SUMIFS(X:X,Z:Z,"*"&$B$10&"*",Y:Y,C4) | G4: =ROUND(MAX(0,MIN(100,(1-E4/IF(D4>0,D4,SUMIFS(Consolidation!$M:$M,Consolidation!$A:$A,"*"&$B$10&"*")/31))*100)),2) | H4: =MIN(1,(G4-$B$3)/($B$4-$B$3))*$B$1 | K4: =SUMIFS(AB:AB,AD:AD,"*"&$B$10&"*",AC:AC,C4) | L4: =ROUND(MAX(0,MIN(100,100*(1-K4/IF(D4>0,D4,SUMIFS(Consolidation!$M:$M,Consolidation!$A:$A,"*"&$B$10&"*")/31)))),2) | M4: =MAX(0,(L4-$B$6)/($B$7-$B$6)*$B$8) | N4: =$B$2+H4+M4 | X4: 10 | Y4: 2026-10-02 | Z4: com.logistics.rider.foodpanda | AB4: 31 | AC4: 2026-10-01 | AD4: com.logistics.rider.foodora
C5: 2026-10-04 | D5: =SUMIFS(V:V,U:U,"*"&$B$10&"*",T:T,C5) | E5: =SUMIFS(X:X,Z:Z,"*"&$B$10&"*",Y:Y,C5) | G5: =ROUND(MAX(0,MIN(100,(1-E5/IF(D5>0,D5,SUMIFS(Consolidation!$M:$M,Consolidation!$A:$A,"*"&$B$10&"*")/31))*100)),2) | H5: =MIN(1,(G5-$B$3)/($B$4-$B$3))*$B$1 | K5: =SUMIFS(AB:AB,AD:AD,"*"&$B$10&"*",AC:AC,C5) | L5: =ROUND(MAX(0,MIN(100,100*(1-K5/IF(D5>0,D5,SUMIFS(Consolidation!$M:$M,Consolidation!$A:$A,"*"&$B$10&"*")/31)))),2) | M5: =MAX(0,(L5-$B$6)/($B$7-$B$6)*$B$8) | N5: =$B$2+H5+M5 | X5: 83 | Y5: 2026-10-02 | Z5: com.logistics.rider.foodpanda | AB5: 1 | AC5: 2026-10-01 | AD5: com.logistics.rider.foodora
A6: Hang minimum | B6: 99.5 | C6: 2026-10-05 | D6: =SUMIFS(V:V,U:U,"*"&$B$10&"*",T:T,C6) | E6: =SUMIFS(X:X,Z:Z,"*"&$B$10&"*",Y:Y,C6) | G6: =ROUND(MAX(0,MIN(100,(1-E6/IF(D6>0,D6,SUMIFS(Consolidation!$M:$M,Consolidation!$A:$A,"*"&$B$10&"*")/31))*100)),2) | H6: =MIN(1,(G6-$B$3)/($B$4-$B$3))*$B$1 | K6: =SUMIFS(AB:AB,AD:AD,"*"&$B$10&"*",AC:AC,C6) | L6: =ROUND(MAX(0,MIN(100,100*(1-K6/IF(D6>0,D6,SUMIFS(Consolidation!$M:$M,Consolidation!$A:$A,"*"&$B$10&"*")/31)))),2) | M6: =MAX(0,(L6-$B$6)/($B$7-$B$6)*$B$8) | N6: =$B$2+H6+M6 | X6: 7 | Y6: 2026-10-03 | Z6: com.logistics.rider.foodpanda | AB6: 134 | AC6: 2026-10-01 | AD6: com.logistics.rider.talabat
A7: Hang maximum | B7: 99.9 | C7: 2026-10-06 | D7: =SUMIFS(V:V,U:U,"*"&$B$10&"*",T:T,C7) | E7: =SUMIFS(X:X,Z:Z,"*"&$B$10&"*",Y:Y,C7) | G7: =ROUND(MAX(0,MIN(100,(1-E7/IF(D7>0,D7,SUMIFS(Consolidation!$M:$M,Consolidation!$A:$A,"*"&$B$10&"*")/31))*100)),2) | H7: =MIN(1,(G7-$B$3)/($B$4-$B$3))*$B$1 | K7: =SUMIFS(AB:AB,AD:AD,"*"&$B$10&"*",AC:AC,C7) | L7: =ROUND(MAX(0,MIN(100,100*(1-K7/IF(D7>0,D7,SUMIFS(Consolidation!$M:$M,Consolidation!$A:$A,"*"&$B$10&"*")/31)))),2) | M7: =MAX(0,(L7-$B$6)/($B$7-$B$6)*$B$8) | N7: =$B$2+H7+M7 | X7: 85 | Y7: 2026-10-03 | Z7: com.logistics.rider.foodpanda | AB7: 1 | AC7: 2026-10-01 | AD7: com.logistics.rider.talabat
A8: Hang part in AQS | B8: 25 | C8: 2026-10-07 | D8: =SUMIFS(V:V,U:U,"*"&$B$10&"*",T:T,C8) | E8: =SUMIFS(X:X,Z:Z,"*"&$B$10&"*",Y:Y,C8) | G8: =ROUND(MAX(0,MIN(100,(1-E8/IF(D8>0,D8,SUMIFS(Consolidation!$M:$M,Consolidation!$A:$A,"*"&$B$10&"*")/31))*100)),2) | H8: =MIN(1,(G8-$B$3)/($B$4-$B$3))*$B$1 | K8: =SUMIFS(AB:AB,AD:AD,"*"&$B$10&"*",AC:AC,C8) | L8: =ROUND(MAX(0,MIN(100,100*(1-K8/IF(D8>0,D8,SUMIFS(Consolidation!$M:$M,Consolidation!$A:$A,"*"&$B$10&"*")/31)))),2) | M8: =MAX(0,(L8-$B$6)/($B$7-$B$6)*$B$8) | N8: =$B$2+H8+M8 | X8: 7 | Y8: 2026-10-04 | Z8: com.logistics.rider.foodpanda | AB8: 5 | AC8: 2026-10-01 | AD8: com.logistics.rider.talabat
C9: 2026-10-08 | D9: =SUMIFS(V:V,U:U,"*"&$B$10&"*",T:T,C9) | E9: =SUMIFS(X:X,Z:Z,"*"&$B$10&"*",Y:Y,C9) | G9: =ROUND(MAX(0,MIN(100,(1-E9/IF(D9>0,D9,SUMIFS(Consolidation!$M:$M,Consolidation!$A:$A,"*"&$B$10&"*")/31))*100)),2) | H9: =MIN(1,(G9-$B$3)/($B$4-$B$3))*$B$1 | K9: =SUMIFS(AB:AB,AD:AD,"*"&$B$10&"*",AC:AC,C9) | L9: =ROUND(MAX(0,MIN(100,100*(1-K9/IF(D9>0,D9,SUMIFS(Consolidation!$M:$M,Consolidation!$A:$A,"*"&$B$10&"*")/31)))),2) | M9: =MAX(0,(L9-$B$6)/($B$7-$B$6)*$B$8) | N9: =$B$2+H9+M9 | X9: 93 | Y9: 2026-10-04 | Z9: com.logistics.rider.foodpanda | AB9: 73 | AC9: 2026-10-01 | AD9: com.logistics.rider.pedidosya
A10: Brand | B10: woowa | C10: 2026-10-09 | D10: =SUMIFS(V:V,U:U,"*"&$B$10&"*",T:T,C10) | E10: =SUMIFS(X:X,Z:Z,"*"&$B$10&"*",Y:Y,C10) | G10: =ROUND(MAX(0,MIN(100,(1-E10/IF(D10>0,D10,SUMIFS(Consolidation!$M:$M,Consolidation!$A:$A,"*"&$B$10&"*")/31))*100)),2) | H10: =MIN(1,(G10-$B$3)/($B$4-$B$3))*$B$1 | K10: =SUMIFS(AB:AB,AD:AD,"*"&$B$10&"*",AC:AC,C10) | L10: =ROUND(MAX(0,MIN(100,100*(1-K10/IF(D10>0,D10,SUMIFS(Consolidation!$M:$M,Consolidation!$A:$A,"*"&$B$10&"*")/31)))),2) | M10: =MAX(0,(L10-$B$6)/($B$7-$B$6)*$B$8) | N10: =$B$2+H10+M10 | X10: 57 | Y10: 2026-10-05 | Z10: com.logistics.rider.foodpanda | AB10: 2 | AC10: 2026-10-01 | AD10: com.logistics.rider.pedidosya
C11: 2026-10-10 | D11: =SUMIFS(V:V,U:U,"*"&$B$10&"*",T:T,C11) | E11: =SUMIFS(X:X,Z:Z,"*"&$B$10&"*",Y:Y,C11) | G11: =ROUND(MAX(0,MIN(100,(1-E11/IF(D11>0,D11,SUMIFS(Consolidation!$M:$M,Consolidation!$A:$A,"*"&$B$10&"*")/31))*100)),2) | H11: =MIN(1,(G11-$B$3)/($B$4-$B$3))*$B$1 | K11: =SUMIFS(AB:AB,AD:AD,"*"&$B$10&"*",AC:AC,C11) | L11: =ROUND(MAX(0,MIN(100,100*(1-K11/IF(D11>0,D11,SUMIFS(Consolidation!$M:$M,Consolidation!$A:$A,"*"&$B$10&"*")/31)))),2) | M11: =MAX(0,(L11-$B$6)/($B$7-$B$6)*$B$8) | N11: =$B$2+H11+M11 | X11: 6 | Y11: 2026-10-05 | Z11: com.logistics.rider.foodpanda | AB11: 52 | AC11: 2026-10-01 | AD11: com.logistics.rider.hungerstation
C12: 2026-10-11 | D12: =SUMIFS(V:V,U:U,"*"&$B$10&"*",T:T,C12) | E12: =SUMIFS(X:X,Z:Z,"*"&$B$10&"*",Y:Y,C12) | G12: =ROUND(MAX(0,MIN(100,(1-E12/IF(D12>0,D12,SUMIFS(Consolidation!$M:$M,Consolidation!$A:$A,"*"&$B$10&"*")/31))*100)),2) | H12: =MIN(1,(G12-$B$3)/($B$4-$B$3))*$B$1 | K12: =SUMIFS(AB:AB,AD:AD,"*"&$B$10&"*",AC:AC,C12) | L12: =ROUND(MAX(0,MIN(100,100*(1-K12/IF(D12>0,D12,SUMIFS(Consolidation!$M:$M,Consolidation!$A:$A,"*"&$B$10&"*")/31)))),2) | M12: =MAX(0,(L12-$B$6)/($B$7-$B$6)*$B$8) | N12: =$B$2+H12+M12 | X12: 7 | Y12: 2026-10-06 | Z12: com.logistics.rider.foodpanda | AB12: 7 | AC12: 2026-10-01 | AD12: com.logistics.rider.hungerstation
C13: 2026-10-12 | D13: =SUMIFS(V:V,U:U,"*"&$B$10&"*",T:T,C13) | E13: =SUMIFS(X:X,Z:Z,"*"&$B$10&"*",Y:Y,C13) | G13: =ROUND(MAX(0,MIN(100,(1-E13/IF(D13>0,D13,SUMIFS(Consolidation!$M:$M,Consolidation!$A:$A,"*"&$B$10&"*")/31))*100)),2) | H13: =MIN(1,(G13-$B$3)/($B$4-$B$3))*$B$1 | K13: =SUMIFS(AB:AB,AD:AD,"*"&$B$10&"*",AC:AC,C13) | L13: =ROUND(MAX(0,MIN(100,100*(1-K13/IF(D13>0,D13,SUMIFS(Consolidation!$M:$M,Consolidation!$A:$A,"*"&$B$10&"*")/31)))),2) | M13: =MAX(0,(L13-$B$6)/($B$7-$B$6)*$B$8) | N13: =$B$2+H13+M13 | X13: 68 | Y13: 2026-10-06 | Z13: com.logistics.rider.foodpanda | AB13: 151 | AC13: 2026-10-01 | AD13: com.logistics.rider.glovo
C14: 2026-10-13 | X14: 84 | Y14: 2026-10-07 | Z14: com.logistics.rider.foodpanda | AB14: 1 | AC14: 2026-10-01 | AD14: com.logistics.rider.glovo
C15: 2026-10-14 | X15: 17 | Y15: 2026-10-07 | Z15: com.logistics.rider.foodpanda | AB15: 8 | AC15: 2026-10-01 | AD15: com.logistics.rider.glovo
C16: 2026-10-15 | X16: 83 | Y16: 2026-10-08 | Z16: com.logistics.rider.foodpanda | AB16: 1 | AC16: 2026-10-01 | AD16: com.logistics.rider.efood
C17: 2026-10-16 | X17: 4 | Y17: 2026-10-08 | Z17: com.logistics.rider.foodpanda | AB17: 19 | AC17: 2026-10-01 | AD17: com.logistics.rider.efood
C18: 2026-10-17 | X18: 96 | Y18: 2026-10-09 | Z18: com.logistics.rider.foodpanda | AB18: 2 | AC18: 2026-10-01 | AD18: com.logistics.rider.foody
C19: 2026-10-18 | X19: 9 | Y19: 2026-10-09 | Z19: com.logistics.rider.foodpanda | AB19: 288 | AC19: 2026-10-02 | AD19: com.logistics.rider.foodpanda
C20: 2026-10-19 | X20: 76 | Y20: 2026-10-10 | Z20: com.logistics.rider.foodpanda | AB20: 32 | AC20: 2026-10-02 | AD20: com.logistics.rider.foodpanda
C21: 2026-10-20 | X21: 7 | Y21: 2026-10-10 | Z21: com.logistics.rider.foodpanda | AB21: 32 | AC21: 2026-10-02 | AD21: com.logistics.rider.foodora
C22: 2026-10-21 | X22: 73 | Y22: 2026-10-11 | Z22: com.logistics.rider.foodpanda | AB22: 1 | AC22: 2026-10-02 | AD22: com.logistics.rider.foodora
C23: 2026-10-22 | X23: 4 | Y23: 2026-10-11 | Z23: com.logistics.rider.foodpanda | AB23: 113 | AC23: 2026-10-02 | AD23: com.logistics.rider.talabat
C24: 2026-10-23 | X24: 67 | Y24: 2026-10-12 | Z24: com.logistics.rider.foodpanda | AB24: 8 | AC24: 2026-10-02 | AD24: com.logistics.rider.talabat
C25: 2026-10-24 | X25: 11 | Y25: 2026-10-12 | Z25: com.logistics.rider.foodpanda | AB25: 3 | AC25: 2026-10-02 | AD25: com.logistics.rider.pedidosya
... C32: 2026-10-31 | X32: 7 | Y32: 2026-10-06 | Z32: com.logistics.rider.foodora | AB32: 1 | AC32: 2026-10-02 | AD32: com.logistics.rider.efood
G33: AVG CFU | I33: October AQS score | L33: AVG Hang-free | N33: Projected AQS including hangs | X33: 9 | Y33: 2026-10-07 | Z33: com.logistics.rider.foodora | AB33: 16 | AC33: 2026-10-02 | AD33: com.logistics.rider.efood
D34: =AVERAGE(D2:D13) | G34: =TRUNC(MAX(0,MIN(100,(1-SUMIFS(X:X,Z:Z,"*"&$B$10&"*")/IF(SUMIFS(V:V,U:U,"*"&$B$10&"*")>0,SUMIFS(V:V,U:U,"*"&$B$10&"*"),SUMIFS(Consolidation!$M:$M,Consolidation!$A:$A,"*"&$B$10&"*")*31))*100)),2) | H34: =AVERAGE(H2:H13) | I34: =$B$2+H34 | L34: =TRUNC(MAX(0,MIN(100,(1-SUMIFS(AB:AB,AD:AD,"*"&$B$10&"*")/IF(SUMIFS(V:V,U:U,"*"&$B$10&"*")>0,SUMIFS(V:V,U:U,"*"&$B$10&"*"),SUMIFS(Consolidation!$M:$M,Consolidation!$A:$A,"*"&$B$10&"*")*31))*100)),2) | M34: =MAX(0,(L34-$B$6)/($B$7-$B$6)*$B$8) | N34: =$B$2+MAX(0,(G34-$B$3)/($B$4-$B$3)*($B$1-$B$8))+M34 | X34: 10 | Y34: 2026-10-08 | Z34: com.logistics.rider.foodora | AB34: 1 | AC34: 2026-10-02 | AD34: com.logistics.rider.foody
X35: 7 | Y35: 2026-10-09 | Z35: com.logistics.rider.foodora | AB35: 4 | AC35: 2026-10-02 | AD35: com.logistics.rider.foody
X36: 10 | Y36: 2026-10-10 | Z36: com.logistics.rider.foodora | AB36: 34 | AC36: 2026-10-03 | AD36: com.logistics.rider.foodpanda
X37: 1 | Y37: 2026-10-11 | Z37: com.logistics.rider.foodora | AB37: 281 | AC37: 2026-10-03 | AD37: com.logistics.rider.foodpanda
X38: 10 | Y38: 2026-10-11 | Z38: com.logistics.rider.foodora | AB38: 2 | AC38: 2026-10-03 | AD38: com.logistics.rider.foodora
X39: 8 | Y39: 2026-10-12 | Z39: com.logistics.rider.foodora | AB39: 23 | AC39: 2026-10-03 | AD39: com.logistics.rider.foodora
X40: 2 | Y40: 2026-10-01 | Z40: com.logistics.rider.talabat | AB40: 9 | AC40: 2026-10-03 | AD40: com.logistics.rider.talabat
X41: 1 | Y41: 2026-10-01 | Z41: com.logistics.rider.talabat | AB41: 122 | AC41: 2026-10-03 | AD41: com.logistics.rider.talabat
X42: 38 | Y42: 2026-10-01 | Z42: com.logistics.rider.talabat | AB42: 3 | AC42: 2026-10-03 | AD42: com.logistics.rider.pedidosya
X43: 2 | Y43: 2026-10-02 | Z43: com.logistics.rider.talabat | AB43: 67 | AC43: 2026-10-03 | AD43: com.logistics.rider.pedidosya
X44: 1 | Y44: 2026-10-02 | Z44: com.logistics.rider.talabat | AB44: 3 | AC44: 2026-10-03 | AD44: com.logistics.rider.hungerstation
X45: 36 | Y45: 2026-10-02 | Z45: com.logistics.rider.talabat | AB45: 50 | AC45: 2026-10-03 | AD45: com.logistics.rider.hungerstation
X46: 36 | Y46: 2026-10-03 | Z46: com.logistics.rider.talabat | AB46: 10 | AC46: 2026-10-03 | AD46: com.logistics.rider.glovo
...

Sheet v4.2640.3
A1: CFU part in AQS | B1: 60 | C1: Date | D1: Total users count (ios_User_Count) | E1: Crashed users count (Query) | G1: CFU % | K1: Hang user count (Query) | L1: Hang free % | N1: Projected AQS including hangs | T1: dt | U1: appId | V1: user_count | X1: CRASH_USERS | Y1: day | Z1: Brand | AB1: HANG_USERS | AC1: day | AD1: Brand
A2: base AQS score | B2: 32.65 | C2: 2026-10-01 | D2: =SUMIFS(V:V,U:U,"*"&$B$10&"*",T:T,C2) | E2: =SUMIFS(X:X,Z:Z,"*"&$B$10&"*",Y:Y,C2) | G2: =ROUND(MAX(0,MIN(100,(1-E2/IF(D2>0,D2,SUMIFS(Consolidation!$M:$M,Consolidation!$A:$A,"*"&$B$10&"*")/31))*100)),2) | H2: =MIN(1,(G2-$B$3)/($B$4-$B$3))*$B$1 | K2: =SUMIFS(AB:AB,AD:AD,"*"&$B$10&"*",AC:AC,C2) | L2: =ROUND(MAX(0,MIN(100,100*(1-K2/IF(D2>0,D2,SUMIFS(Consolidation!$M:$M,Consolidation!$A:$A,"*"&$B$10&"*")/31)))),2) | M2: =MAX(0,(L2-$B$6)/($B$7-$B$6)*$B$8) | N2: =$B$2+H2+M2 | X2: 3 | Y2: 2026-10-01 | Z2: com.logistics.rider.foodpanda | AB2: 16 | AC2: 2026-10-01 | AD2: com.logistics.rider.foodpanda
A3: CFU minimum | B3: 99.5 | C3: 2026-10-02 | D3: =SUMIFS(V:V,U:U,"*"&$B$10&"*",T:T,C3) | E3: =SUMIFS(X:X,Z:Z,"*"&$B$10&"*",Y:Y,C3) | G3: =ROUND(MAX(0,MIN(100,(1-E3/IF(D3>0,D3,SUMIFS(Consolidation!$M:$M,Consolidation!$A:$A,"*"&$B$10&"*")/31))*100)),2) | H3: =MIN(1,(G3-$B$3)/($B$4-$B$3))*$B$1 | K3: =SUMIFS(AB:AB,AD:AD,"*"&$B$10&"*",AC:AC,C3) | L3: =ROUND(MAX(0,MIN(100,100*(1-K3/IF(D3>0,D3,SUMIFS(Consolidation!$M:$M,Consolidation!$A:$A,"*"&$B$10&"*")/31)))),2) | M3: =MAX(0,(L3-$B$6)/($B$7-$B$6)*$B$8) | N3: =$B$2+H3+M3 | X3: 15 | Y3: 2026-10-02 | Z3: com.logistics.rider.foodpanda | AB3: 6 | AC3: 2026-10-01 | AD3: com.logistics.rider.foodora
A4: CFU maximum | B4: 99.9 | C4: 2026-10-03 | D4: =SUMIFS(V:V,U:U,"*"&$B$10&"*",T:T,C4) | E4: =SUMIFS(X:X,Z:Z,"*"&$B$10&"*",Y:Y,C4) | G4: =ROUND(MAX(0,MIN(100,(1-E4/IF(D4>0,D4,SUMIFS(Consolidation!$M:$M,Consolidation!$A:$A,"*"&$B$10&"*")/31))*100)),2) | H4: =MIN(1,(G4-$B$3)/($B$4-$B$3))*$B$1 | K4: =SUMIFS(AB:AB,AD:AD,"*"&$B$10&"*",AC:AC,C4) | L4: =ROUND(MAX(0,MIN(100,100*(1-K4/IF(D4>0,D4,SUMIFS(Consolidation!$M:$M,Consolidation!$A:$A,"*"&$B$10&"*")/31)))),2) | M4: =MAX(0,(L4-$B$6)/($B$7-$B$6)*$B$8) | N4: =$B$2+H4+M4 | X4: 29 | Y4: 2026-10-03 | Z4: com.logistics.rider.foodpanda | AB4: 9 | AC4: 2026-10-01 | AD4: com.logistics.rider.talabat
C5: 2026-10-04 | D5: =SUMIFS(V:V,U:U,"*"&$B$10&"*",T:T,C5) | E5: =SUMIFS(X:X,Z:Z,"*"&$B$10&"*",Y:Y,C5) | G5: =ROUND(MAX(0,MIN(100,(1-E5/IF(D5>0,D5,SUMIFS(Consolidation!$M:$M,Consolidation!$A:$A,"*"&$B$10&"*")/31))*100)),2) | H5: =MIN(1,(G5-$B$3)/($B$4-$B$3))*$B$1 | K5: =SUMIFS(AB:AB,AD:AD,"*"&$B$10&"*",AC:AC,C5) | L5: =ROUND(MAX(0,MIN(100,100*(1-K5/IF(D5>0,D5,SUMIFS(Consolidation!$M:$M,Consolidation!$A:$A,"*"&$B$10&"*")/31)))),2) | M5: =MAX(0,(L5-$B$6)/($B$7-$B$6)*$B$8) | N5: =$B$2+H5+M5 | X5: 42 | Y5: 2026-10-04 | Z5: com.logistics.rider.foodpanda | AB5: 3 | AC5: 2026-10-01 | AD5: com.logistics.rider.pedidosya
A6: Hang minimum | B6: 99.5 | C6: 2026-10-05 | D6: =SUMIFS(V:V,U:U,"*"&$B$10&"*",T:T,C6) | E6: =SUMIFS(X:X,Z:Z,"*"&$B$10&"*",Y:Y,C6) | G6: =ROUND(MAX(0,MIN(100,(1-E6/IF(D6>0,D6,SUMIFS(Consolidation!$M:$M,Consolidation!$A:$A,"*"&$B$10&"*")/31))*100)),2) | H6: =MIN(1,(G6-$B$3)/($B$4-$B$3))*$B$1 | K6: =SUMIFS(AB:AB,AD:AD,"*"&$B$10&"*",AC:AC,C6) | L6: =ROUND(MAX(0,MIN(100,100*(1-K6/IF(D6>0,D6,SUMIFS(Consolidation!$M:$M,Consolidation!$A:$A,"*"&$B$10&"*")/31)))),2) | M6: =MAX(0,(L6-$B$6)/($B$7-$B$6)*$B$8) | N6: =$B$2+H6+M6 | X6: 20 | Y6: 2026-10-05 | Z6: com.logistics.rider.foodpanda | AB6: 8 | AC6: 2026-10-01 | AD6: com.logistics.rider.hungerstation
A7: Hang maximum | B7: 99.9 | C7: 2026-10-06 | D7: =SUMIFS(V:V,U:U,"*"&$B$10&"*",T:T,C7) | E7: =SUMIFS(X:X,Z:Z,"*"&$B$10&"*",Y:Y,C7) | G7: =ROUND(MAX(0,MIN(100,(1-E7/IF(D7>0,D7,SUMIFS(Consolidation!$M:$M,Consolidation!$A:$A,"*"&$B$10&"*")/31))*100)),2) | H7: =MIN(1,(G7-$B$3)/($B$4-$B$3))*$B$1 | K7: =SUMIFS(AB:AB,AD:AD,"*"&$B$10&"*",AC:AC,C7) | L7: =ROUND(MAX(0,MIN(100,100*(1-K7/IF(D7>0,D7,SUMIFS(Consolidation!$M:$M,Consolidation!$A:$A,"*"&$B$10&"*")/31)))),2) | M7: =MAX(0,(L7-$B$6)/($B$7-$B$6)*$B$8) | N7: =$B$2+H7+M7 | X7: 31 | Y7: 2026-10-06 | Z7: com.logistics.rider.foodpanda | AB7: 15 | AC7: 2026-10-01 | AD7: com.logistics.rider.glovo
A8: Hang part in AQS | B8: 25 | C8: 2026-10-07 | D8: =SUMIFS(V:V,U:U,"*"&$B$10&"*",T:T,C8) | E8: =SUMIFS(X:X,Z:Z,"*"&$B$10&"*",Y:Y,C8) | G8: =ROUND(MAX(0,MIN(100,(1-E8/IF(D8>0,D8,SUMIFS(Consolidation!$M:$M,Consolidation!$A:$A,"*"&$B$10&"*")/31))*100)),2) | H8: =MIN(1,(G8-$B$3)/($B$4-$B$3))*$B$1 | K8: =SUMIFS(AB:AB,AD:AD,"*"&$B$10&"*",AC:AC,C8) | L8: =ROUND(MAX(0,MIN(100,100*(1-K8/IF(D8>0,D8,SUMIFS(Consolidation!$M:$M,Consolidation!$A:$A,"*"&$B$10&"*")/31)))),2) | M8: =MAX(0,(L8-$B$6)/($B$7-$B$6)*$B$8) | N8: =$B$2+H8+M8 | X8: 46 | Y8: 2026-10-07 | Z8: com.logistics.rider.foodpanda | AB8: 1 | AC8: 2026-10-01 | AD8: com.logistics.rider.efood
C9: 2026-10-08 | D9: =SUMIFS(V:V,U:U,"*"&$B$10&"*",T:T,C9) | E9: =SUMIFS(X:X,Z:Z,"*"&$B$10&"*",Y:Y,C9) | G9: =ROUND(MAX(0,MIN(100,(1-E9/IF(D9>0,D9,SUMIFS(Consolidation!$M:$M,Consolidation!$A:$A,"*"&$B$10&"*")/31))*100)),2) | H9: =MIN(1,(G9-$B$3)/($B$4-$B$3))*$B$1 | K9: =SUMIFS(AB:AB,AD:AD,"*"&$B$10&"*",AC:AC,C9) | L9: =ROUND(MAX(0,MIN(100,100*(1-K9/IF(D9>0,D9,SUMIFS(Consolidation!$M:$M,Consolidation!$A:$A,"*"&$B$10&"*")/31)))),2) | M9: =MAX(0,(L9-$B$6)/($B$7-$B$6)*$B$8) | N9: =$B$2+H9+M9 | X9: 47 | Y9: 2026-10-08 | Z9: com.logistics.rider.foodpanda | AB9: 2 | AC9: 2026-10-01 | AD9: com.logistics.rider.foody
A10: Brand | B10: woowa | C10: 2026-10-09 | D10: =SUMIFS(V:V,U:U,"*"&$B$10&"*",T:T,C10) | E10: =SUMIFS(X:X,Z:Z,"*"&$B$10&"*",Y:Y,C10) | G10: =ROUND(MAX(0,MIN(100,(1-E10/IF(D10>0,D10,SUMIFS(Consolidation!$M:$M,Consolidation!$A:$A,"*"&$B$10&"*")/31))*100)),2) | H10: =MIN(1,(G10-$B$3)/($B$4-$B$3))*$B$1 | K10: =SUMIFS(AB:AB,AD:AD,"*"&$B$10&"*",AC:AC,C10) | L10: =ROUND(MAX(0,MIN(100,100*(1-K10/IF(D10>0,D10,SUMIFS(Consolidation!$M:$M,Consolidation!$A:$A,"*"&$B$10&"*")/31)))),2) | M10: =MAX(0,(L10-$B$6)/($B$7-$B$6)*$B$8) | N10: =$B$2+H10+M10 | X10: 38 | Y10: 2026-10-09 | Z10: com.logistics.rider.foodpanda | AB10: 46 | AC10: 2026-10-02 | AD10: com.logistics.rider.foodpanda
C11: 2026-10-10 | D11: =SUMIFS(V:V,U:U,"*"&$B$10&"*",T:T,C11) | E11: =SUMIFS(X:X,Z:Z,"*"&$B$10&"*",Y:Y,C11) | G11: =ROUND(MAX(0,MIN(100,(1-E11/IF(D11>0,D11,SUMIFS(Consolidation!$M:$M,Consolidation!$A:$A,"*"&$B$10&"*")/31))*100)),2) | H11: =MIN(1,(G11-$B$3)/($B$4-$B$3))*$B$1 | K11: =SUMIFS(AB:AB,AD:AD,"*"&$B$10&"*",AC:AC,C11) | L11: =ROUND(MAX(0,MIN(100,100*(1-K11/IF(D11>0,D11,SUMIFS(Consolidation!$M:$M,Consolidation!$A:$A,"*"&$B$10&"*")/31)))),2) | M11: =MAX(0,(L11-$B$6)/($B$7-$B$6)*$B$8) | N11: =$B$2+H11+M11 | X11: 29 | Y11: 2026-10-10 | Z11: com.logistics.rider.foodpanda | AB11: 11 | AC11: 2026-10-02 | AD11: com.logistics.rider.foodora
C12: 2026-10-11 | D12: =SUMIFS(V:V,U:U,"*"&$B$10&"*",T:T,C12) | E12: =SUMIFS(X:X,Z:Z,"*"&$B$10&"*",Y:Y,C12) | G12: =ROUND(MAX(0,MIN(100,(1-E12/IF(D12>0,D12,SUMIFS(Consolidation!$M:$M,Consolidation!$A:$A,"*"&$B$10&"*")/31))*100)),2) | H12: =MIN(1,(G12-$B$3)/($B$4-$B$3))*$B$1 | K12: =SUMIFS(AB:AB,AD:AD,"*"&$B$10&"*",AC:AC,C12) | L12: =ROUND(MAX(0,MIN(100,100*(1-K12/IF(D12>0,D12,SUMIFS(Consolidation!$M:$M,Consolidation!$A:$A,"*"&$B$10&"*")/31)))),2) | M12: =MAX(0,(L12-$B$6)/($B$7-$B$6)*$B$8) | N12: =$B$2+H12+M12 | X12: 22 | Y12: 2026-10-11 | Z12: com.logistics.rider.foodpanda | AB12: 21 | AC12: 2026-10-02 | AD12: com.logistics.rider.talabat
C13: 2026-10-12 | D13: =SUMIFS(V:V,U:U,"*"&$B$10&"*",T:T,C13) | E13: =SUMIFS(X:X,Z:Z,"*"&$B$10&"*",Y:Y,C13) | G13: =ROUND(MAX(0,MIN(100,(1-E13/IF(D13>0,D13,SUMIFS(Consolidation!$M:$M,Consolidation!$A:$A,"*"&$B$10&"*")/31))*100)),2) | H13: =MIN(1,(G13-$B$3)/($B$4-$B$3))*$B$1 | K13: =SUMIFS(AB:AB,AD:AD,"*"&$B$10&"*",AC:AC,C13) | L13: =ROUND(MAX(0,MIN(100,100*(1-K13/IF(D13>0,D13,SUMIFS(Consolidation!$M:$M,Consolidation!$A:$A,"*"&$B$10&"*")/31)))),2) | M13: =MAX(0,(L13-$B$6)/($B$7-$B$6)*$B$8) | N13: =$B$2+H13+M13 | X13: 20 | Y13: 2026-10-12 | Z13: com.logistics.rider.foodpanda | AB13: 17 | AC13: 2026-10-02 | AD13: com.logistics.rider.pedidosya
C14: 2026-10-13 | X14: 3 | Y14: 2026-10-02 | Z14: com.logistics.rider.foodora | AB14: 8 | AC14: 2026-10-02 | AD14: com.logistics.rider.hungerstation
C15: 2026-10-14 | X15: 6 | Y15: 2026-10-03 | Z15: com.logistics.rider.foodora | AB15: 28 | AC15: 2026-10-02 | AD15: com.logistics.rider.glovo
C16: 2026-10-15 | X16: 4 | Y16: 2026-10-04 | Z16: com.logistics.rider.foodora | AB16: 1 | AC16: 2026-10-02 | AD16: com.logistics.rider.woowabros
C17: 2026-10-16 | X17: 5 | Y17: 2026-10-05 | Z17: com.logistics.rider.foodora | AB17: 1 | AC17: 2026-10-02 | AD17: com.logistics.rider.efood
C18: 2026-10-17 | X18: 1 | Y18: 2026-10-06 | Z18: com.logistics.rider.foodora | AB18: 1 | AC18: 2026-10-02 | AD18: com.logistics.rider.foody
C19: 2026-10-18 | X19: 5 | Y19: 2026-10-07 | Z19: com.logistics.rider.foodora | AB19: 76 | AC19: 2026-10-03 | AD19: com.logistics.rider.foodpanda
C20: 2026-10-19 | X20: 7 | Y20: 2026-10-08 | Z20: com.logistics.rider.foodora | AB20: 8 | AC20: 2026-10-03 | AD20: com.logistics.rider.foodora
C21: 2026-10-20 | X21: 3 | Y21: 2026-10-09 | Z21: com.logistics.rider.foodora | AB21: 40 | AC21: 2026-10-03 | AD21: com.logistics.rider.talabat
C22: 2026-10-21 | X22: 3 | Y22: 2026-10-10 | Z22: com.logistics.rider.foodora | AB22: 17 | AC22: 2026-10-03 | AD22: com.logistics.rider.pedidosya
C23: 2026-10-22 | X23: 3 | Y23: 2026-10-11 | Z23: com.logistics.rider.foodora | AB23: 11 | AC23: 2026-10-03 | AD23: com.logistics.rider.hungerstation
C24: 2026-10-23 | X24: 4 | Y24: 2026-10-12 | Z24: com.logistics.rider.foodora | AB24: 47 | AC24: 2026-10-03 | AD24: com.logistics.rider.glovo
C25: 2026-10-24 | X25: 5 | Y25: 2026-10-01 | Z25: com.logistics.rider.talabat | AB25: 3 | AC25: 2026-10-03 | AD25: com.logistics.rider.efood
... C32: 2026-10-31 | X32: 16 | Y32: 2026-10-08 | Z32: com.logistics.rider.talabat | AB32: 5 | AC32: 2026-10-04 | AD32: com.logistics.rider.efood
G33: AVG CFU | I33: October AQS score | L33: AVG Hang-free | N33: Projected AQS including hangs | X33: 17 | Y33: 2026-10-09 | Z33: com.logistics.rider.talabat | AB33: 112 | AC33: 2026-10-05 | AD33: com.logistics.rider.foodpanda
D34: =AVERAGE(D2:D13) | G34: =TRUNC(MAX(0,MIN(100,(1-SUMIFS(X:X,Z:Z,"*"&$B$10&"*")/IF(SUMIFS(V:V,U:U,"*"&$B$10&"*")>0,SUMIFS(V:V,U:U,"*"&$B$10&"*"),SUMIFS(Consolidation!$M:$M,Consolidation!$A:$A,"*"&$B$10&"*")*31))*100)),2) | H34: =AVERAGE(H2:H13) | I34: =$B$2+H34 | L34: =TRUNC(MAX(0,MIN(100,(1-SUMIFS(AB:AB,AD:AD,"*"&$B$10&"*")/IF(SUMIFS(V:V,U:U,"*"&$B$10&"*")>0,SUMIFS(V:V,U:U,"*"&$B$10&"*"),SUMIFS(Consolidation!$M:$M,Consolidation!$A:$A,"*"&$B$10&"*")*31))*100)),2) | M34: =MAX(0,(L34-$B$6)/($B$7-$B$6)*$B$8) | N34: =$B$2+MAX(0,(G34-$B$3)/($B$4-$B$3)*($B$1-$B$8))+M34 | X34: 12 | Y34: 2026-10-10 | Z34: com.logistics.rider.talabat | AB34: 7 | AC34: 2026-10-05 | AD34: com.logistics.rider.foodora
X35: 10 | Y35: 2026-10-11 | Z35: com.logistics.rider.talabat | AB35: 40 | AC35: 2026-10-05 | AD35: com.logistics.rider.talabat
X36: 13 | Y36: 2026-10-12 | Z36: com.logistics.rider.talabat | AB36: 27 | AC36: 2026-10-05 | AD36: com.logistics.rider.pedidosya
X37: 4 | Y37: 2026-10-02 | Z37: com.logistics.rider.pedidosya | AB37: 26 | AC37: 2026-10-05 | AD37: com.logistics.rider.hungerstation
X38: 5 | Y38: 2026-10-03 | Z38: com.logistics.rider.pedidosya | AB38: 69 | AC38: 2026-10-05 | AD38: com.logistics.rider.glovo
X39: 6 | Y39: 2026-10-04 | Z39: com.logistics.rider.pedidosya | AB39: 3 | AC39: 2026-10-05 | AD39: com.logistics.rider.efood
X40: 6 | Y40: 2026-10-05 | Z40: com.logistics.rider.pedidosya | AB40: 2 | AC40: 2026-10-05 | AD40: com.logistics.rider.foody
X41: 8 | Y41: 2026-10-06 | Z41: com.logistics.rider.pedidosya | AB41: 142 | AC41: 2026-10-06 | AD41: com.logistics.rider.foodpanda
X42: 5 | Y42: 2026-10-07 | Z42: com.logistics.rider.pedidosya | AB42: 9 | AC42: 2026-10-06 | AD42: com.logistics.rider.foodora
X43: 6 | Y43: 2026-10-08 | Z43: com.logistics.rider.pedidosya | AB43: 67 | AC43: 2026-10-06 | AD43: com.logistics.rider.talabat
X44: 7 | Y44: 2026-10-09 | Z44: com.logistics.rider.pedidosya | AB44: 19 | AC44: 2026-10-06 | AD44: com.logistics.rider.pedidosya
X45: 6 | Y45: 2026-10-10 | Z45: com.logistics.rider.pedidosya | AB45: 27 | AC45: 2026-10-06 | AD45: com.logistics.rider.hungerstation
X46: 4 | Y46: 2026-10-11 | Z46: com.logistics.rider.pedidosya | AB46: 108 | AC46: 2026-10-06 | AD46: com.logistics.rider.glovo
...

Sheet v4.2640.3 Cons
A1: Brand | B1: Crash free users | C1: App Hangs | D1: App size | E1: ASTI | F1: STTI | G1: Frozen Frames | H1: Skipped Frames | I1: Riders count | J1: Weight Rider ID
A2: Foodpanda | B2: =TRUNC(MAX(0,MIN(100,(1-SUMIFS('v4.2640.3'!$X:$X,'v4.2640.3'!$Z:$Z,"*"&$A2&"*")/IF(SUMIFS('v4.2640.3'!$V:$V,'v4.2640.3'!$U:$U,"*"&$A2&"*")>0,SUMIFS('v4.2640.3'!$V:$V,'v4.2640.3'!$U:$U,"*"&$A2&"*"),I2*31))*100)),2) | C2: =TRUNC(MAX(0,MIN(100,(1-SUMIFS('v4.2640.3'!$AB:$AB,'v4.2640.3'!$AD:$AD,"*"&$A2&"*")/IF(SUMIFS('v4.2640.3'!$V:$V,'v4.2640.3'!$U:$U,"*"&$A2&"*")>0,SUMIFS('v4.2640.3'!$V:$V,'v4.2640.3'!$U:$U,"*"&$A2&"*"),I2*31))*100)),2) | D2: 77.8 | E2: 4.34 | F2: 0.988 | G2: 1.2 | H2: 0.57 | I2: 78203 | J2: 0.3966
A3: Foodora | B3: =TRUNC(MAX(0,MIN(100,(1-SUMIFS('v4.2640.3'!$X:$X,'v4.2640.3'!$Z:$Z,"*"&$A3&"*")/IF(SUMIFS('v4.2640.3'!$V:$V,'v4.2640.3'!$U:$U,"*"&$A3&"*")>0,SUMIFS('v4.2640.3'!$V:$V,'v4.2640.3'!$U:$U,"*"&$A3&"*"),I3*31))*100)),2) | C3: =TRUNC(MAX(0,MIN(100,(1-SUMIFS('v4.2640.3'!$AB:$AB,'v4.2640.3'!$AD:$AD,"*"&$A3&"*")/IF(SUMIFS('v4.2640.3'!$V:$V,'v4.2640.3'!$U:$U,"*"&$A3&"*")>0,SUMIFS('v4.2640.3'!$V:$V,'v4.2640.3'!$U:$U,"*"&$A3&"*"),I3*31))*100)),2) | D3: 83.2 | E3: 4.34 | F3: 0.988 | G3: 1.2 | H3: 0.57 | I3: 14946 | J3: 0.0758
A4: Talabat | B4: =TRUNC(MAX(0,MIN(100,(1-SUMIFS('v4.2640.3'!$X:$X,'v4.2640.3'!$Z:$Z,"*"&$A4&"*")/IF(SUMIFS('v4.2640.3'!$V:$V,'v4.2640.3'!$U:$U,"*"&$A4&"*")>0,SUMIFS('v4.2640.3'!$V:$V,'v4.2640.3'!$U:$U,"*"&$A4&"*"),I4*31))*100)),2) | C4: =TRUNC(MAX(0,MIN(100,(1-SUMIFS('v4.2640.3'!$AB:$AB,'v4.2640.3'!$AD:$AD,"*"&$A4&"*")/IF(SUMIFS('v4.2640.3'!$V:$V,'v4.2640.3'!$U:$U,"*"&$A4&"*")>0,SUMIFS('v4.2640.3'!$V:$V,'v4.2640.3'!$U:$U,"*"&$A4&"*"),I4*31))*100)),2) | D4: 77.8 | E4: 4.34 | F4: 0.988 | G4: 1.2 | H4: 0.57 | I4: 16988 | J4: 0.0861
A5: pedidosya | B5: =TRUNC(MAX(0,MIN(100,(1-SUMIFS('v4.2640.3'!$X:$X,'v4.2640.3'!$Z:$Z,"*"&$A5&"*")/IF(SUMIFS('v4.2640.3'!$V:$V,'v4.2640.3'!$U:$U,"*"&$A5&"*")>0,SUMIFS('v4.2640.3'!$V:$V,'v4.2640.3'!$U:$U,"*"&$A5&"*"),I5*31))*100)),2) | C5: =TRUNC(MAX(0,MIN(100,(1-SUMIFS('v4.2640.3'!$AB:$AB,'v4.2640.3'!$AD:$AD,"*"&$A5&"*")/IF(SUMIFS('v4.2640.3'!$V:$V,'v4.2640.3'!$U:$U,"*"&$A5&"*")>0,SUMIFS('v4.2640.3'!$V:$V,'v4.2640.3'!$U:$U,"*"&$A5&"*"),I5*31))*100)),2) | D5: 68.4 | E5: 4.34 | F5: 0.988 | G5: 1.2 | H5: 0.57 | I5: 20641 | J5: 0.1047
A6: HungerStation | B6: =TRUNC(MAX(0,MIN(100,(1-SUMIFS('v4.2640.3'!$X:$X,'v4.2640.3'!$Z:$Z,"*"&$A6&"*")/IF(SUMIFS('v4.2640.3'!$V:$V,'v4.2640.3'!$U:$U,"*"&$A6&"*")>0,SUMIFS('v4.2640.3'!$V:$V,'v4.2640.3'!$U:$U,"*"&$A6&"*"),I6*31))*100)),2) | C6: =TRUNC(MAX(0,MIN(100,(1-SUMIFS('v4.2640.3'!$AB:$AB,'v4.2640.3'!$AD:$AD,"*"&$A6&"*")/IF(SUMIFS('v4.2640.3'!$V:$V,'v4.2640.3'!$U:$U,"*"&$A6&"*")>0,SUMIFS('v4.2640.3'!$V:$V,'v4.2640.3'!$U:$U,"*"&$A6&"*"),I6*31))*100)),2) | D6: 78.3 | E6: 4.34 | F6: 0.988 | G6: 1.2 | H6: 0.57 | I6: 10630 | J6: 0.0539
A7: Yemeksepeti | B7: =TRUNC(MAX(0,MIN(100,(1-SUMIFS('v4.2640.3'!$X:$X,'v4.2640.3'!$Z:$Z,"*"&$A7&"*")/IF(SUMIFS('v4.2640.3'!$V:$V,'v4.2640.3'!$U:$U,"*"&$A7&"*")>0,SUMIFS('v4.2640.3'!$V:$V,'v4.2640.3'!$U:$U,"*"&$A7&"*"),I7*31))*100)),2) | C7: =TRUNC(MAX(0,MIN(100,(1-SUMIFS('v4.2640.3'!$AB:$AB,'v4.2640.3'!$AD:$AD,"*"&$A7&"*")/IF(SUMIFS('v4.2640.3'!$V:$V,'v4.2640.3'!$U:$U,"*"&$A7&"*")>0,SUMIFS('v4.2640.3'!$V:$V,'v4.2640.3'!$U:$U,"*"&$A7&"*"),I7*31))*100)),2) | D7: 78.3 | E7: 4.34 | F7: 0.988 | G7: 1.2 | H7: 0.57 | I7: 2186 | J7: 0.0111
A8: Glovo | B8: =TRUNC(MAX(0,MIN(100,(1-SUMIFS('v4.2640.3'!$X:$X,'v4.2640.3'!$Z:$Z,"*"&$A8&"*")/IF(SUMIFS('v4.2640.3'!$V:$V,'v4.2640.3'!$U:$U,"*"&$A8&"*")>0,SUMIFS('v4.2640.3'!$V:$V,'v4.2640.3'!$U:$U,"*"&$A8&"*"),I8*31))*100)),2) | C8: =TRUNC(MAX(0,MIN(100,(1-SUMIFS('v4.2640.3'!$AB:$AB,'v4.2640.3'!$AD:$AD,"*"&$A8&"*")/IF(SUMIFS('v4.2640.3'!$V:$V,'v4.2640.3'!$U:$U,"*"&$A8&"*")>0,SUMIFS('v4.2640.3'!$V:$V,'v4.2640.3'!$U:$U,"*"&$A8&"*"),I8*31))*100)),2) | D8: 77.9 | E8: 4.34 | F8: 0.988 | G8: 1.2 | H8: 0.57 | I8: 46896 | J8: 0.2378
A9: Woowa | B9: =TRUNC(MAX(0,MIN(100,(1-SUMIFS('v4.2640.3'!$X:$X,'v4.2640.3'!$Z:$Z,"*"&$A9&"*")/IF(SUMIFS('v4.2640.3'!$V:$V,'v4.2640.3'!$U:$U,"*"&$A9&"*")>0,SUMIFS('v4.2640.3'!$V:$V,'v4.2640.3'!$U:$U,"*"&$A9&"*"),I9*31))*100)),2) | C9: =TRUNC(MAX(0,MIN(100,(1-SUMIFS('v4.2640.3'!$AB:$AB,'v4.2640.3'!$AD:$AD,"*"&$A9&"*")/IF(SUMIFS('v4.2640.3'!$V:$V,'v4.2640.3'!$U:$U,"*"&$A9&"*")>0,SUMIFS('v4.2640.3'!$V:$V,'v4.2640.3'!$U:$U,"*"&$A9&"*"),I9*31))*100)),2) | D9: 78 | E9: 4.34 | F9: 0.988 | G9: 1.2 | H9: 0.57 | I9: 731 | J9: 0.0037
A10: efood | B10: =TRUNC(MAX(0,MIN(100,(1-SUMIFS('v4.2640.3'!$X:$X,'v4.2640.3'!$Z:$Z,"*"&$A10&"*")/IF(SUMIFS('v4.2640.3'!$V:$V,'v4.2640.3'!$U:$U,"*"&$A10&"*")>0,SUMIFS('v4.2640.3'!$V:$V,'v4.2640.3'!$U:$U,"*"&$A10&"*"),I10*31))*100)),2) | C10: =TRUNC(MAX(0,MIN(100,(1-SUMIFS('v4.2640.3'!$AB:$AB,'v4.2640.3'!$AD:$AD,"*"&$A10&"*")/IF(SUMIFS('v4.2640.3'!$V:$V,'v4.2640.3'!$U:$U,"*"&$A10&"*")>0,SUMIFS('v4.2640.3'!$V:$V,'v4.2640.3'!$U:$U,"*"&$A10&"*"),I10*31))*100)),2) | D10: 68.1 | E10: 4.34 | F10: 0.988 | G10: 1.2 | H10: 0.57 | I10: 5258 | J10: 0.0267
A11: Foody | B11: =TRUNC(MAX(0,MIN(100,(1-SUMIFS('v4.2640.3'!$X:$X,'v4.2640.3'!$Z:$Z,"*"&$A11&"*")/IF(SUMIFS('v4.2640.3'!$V:$V,'v4.2640.3'!$U:$U,"*"&$A11&"*")>0,SUMIFS('v4.2640.3'!$V:$V,'v4.2640.3'!$U:$U,"*"&$A11&"*"),I11*31))*100)),2) | C11: =TRUNC(MAX(0,MIN(100,(1-SUMIFS('v4.2640.3'!$AB:$AB,'v4.2640.3'!$AD:$AD,"*"&$A11&"*")/IF(SUMIFS('v4.2640.3'!$V:$V,'v4.2640.3'!$U:$U,"*"&$A11&"*")>0,SUMIFS('v4.2640.3'!$V:$V,'v4.2640.3'!$U:$U,"*"&$A11&"*"),I11*31))*100)),2) | D11: 68.1 | E11: 4.34 | F11: 0.988 | G11: 1.2 | H11: 0.57 | I11: 729 | J11: 0.0037
A12: AVG | B12: =TRUNC(SUMPRODUCT(B2:B11,J2:J11),2) | C12: =TRUNC(SUMPRODUCT(C2:C11,J2:J11),2) | D12: =TRUNC(SUMPRODUCT(D2:D11,J2:J11),2) | E12: =TRUNC(SUMPRODUCT(E2:E11,J2:J11),2) | F12: =TRUNC(SUMPRODUCT(F2:F11,J2:J11),2) | G12: =TRUNC(SUMPRODUCT(G2:G11,J2:J11),2) | H12: =TRUNC(SUMPRODUCT(H2:H11,J2:J11),2)
A13: AQS | B13: =MIN(100,MAX(0,(((B12-99.7)/(99.9-99.7))*50)+50))*35% | C13: =MIN(100,MAX(0,(((C12-99.7)/(99.9-99.7))*50)+50))*25% | D13: =MIN(100,MAX(0,(((D12-75)/(60-75))*50)+50))*2% | E13: =MIN(100,MAX(0,(((E12-4)/(2-4))*50)+50))*10% | F13: =MIN(100,MAX(0,(((F12-1.5)/(0.5-1.5))*50)+50))*10% | G13: =MIN(100,MAX(0,(((G12-3)/(1-3))*50)+50))*13% | H13: =MIN(100,MAX(0,(((H12-2)/(1-2))*50)+50))*5% | J13: =SUM(J2:J11)
A15: FINAL AQS = | B15: =ROUND(SUM(B13:H13),2)
